2019-08-29 09:52:37,334 ERROR: Exception on /auth/register [POST] [in /Users/hui/anaconda3/lib/python3.7/site-packages/flask/app.py:1891]
Traceback (most recent call last):
  File "/Users/hui/anaconda3/lib/python3.7/site-packages/pymysql/connections.py", line 583, in connect
    **kwargs)
  File "/Users/hui/anaconda3/lib/python3.7/socket.py", line 727, in create_connection
    raise err
  File "/Users/hui/anaconda3/lib/python3.7/socket.py", line 716, in create_connection
    sock.connect(sa)
ConnectionRefusedError: [Errno 61] Connection refused

During handling of the above exception, another exception occurred:

Traceback (most recent call last):
  File "/Users/hui/anaconda3/lib/python3.7/site-packages/sqlalchemy/engine/base.py", line 2265, in _wrap_pool_connect
    return fn()
  File "/Users/hui/anaconda3/lib/python3.7/site-packages/sqlalchemy/pool/base.py", line 363, in connect
    return _ConnectionFairy._checkout(self)
  File "/Users/hui/anaconda3/lib/python3.7/site-packages/sqlalchemy/pool/base.py", line 760, in _checkout
    fairy = _ConnectionRecord.checkout(pool)
  File "/Users/hui/anaconda3/lib/python3.7/site-packages/sqlalchemy/pool/base.py", line 492, in checkout
    rec = pool._do_get()
  File "/Users/hui/anaconda3/lib/python3.7/site-packages/sqlalchemy/pool/impl.py", line 139, in _do_get
    self._dec_overflow()
  File "/Users/hui/anaconda3/lib/python3.7/site-packages/sqlalchemy/util/langhelpers.py", line 68, in __exit__
    compat.reraise(exc_type, exc_value, exc_tb)
  File "/Users/hui/anaconda3/lib/python3.7/site-packages/sqlalchemy/util/compat.py", line 153, in reraise
    raise value
  File "/Users/hui/anaconda3/lib/python3.7/site-packages/sqlalchemy/pool/impl.py", line 136, in _do_get
    return self._create_connection()
  File "/Users/hui/anaconda3/lib/python3.7/site-packages/sqlalchemy/pool/base.py", line 308, in _create_connection
    return _ConnectionRecord(self)
  File "/Users/hui/anaconda3/lib/python3.7/site-packages/sqlalchemy/pool/base.py", line 437, in __init__
    self.__connect(first_connect_check=True)
  File "/Users/hui/anaconda3/lib/python3.7/site-packages/sqlalchemy/pool/base.py", line 639, in __connect
    connection = pool._invoke_creator(self)
  File "/Users/hui/anaconda3/lib/python3.7/site-packages/sqlalchemy/engine/strategies.py", line 114, in connect
    return dialect.connect(*cargs, **cparams)
  File "/Users/hui/anaconda3/lib/python3.7/site-packages/sqlalchemy/engine/default.py", line 453, in connect
    return self.dbapi.connect(*cargs, **cparams)
  File "/Users/hui/anaconda3/lib/python3.7/site-packages/pymysql/__init__.py", line 94, in Connect
    return Connection(*args, **kwargs)
  File "/Users/hui/anaconda3/lib/python3.7/site-packages/pymysql/connections.py", line 325, in __init__
    self.connect()
  File "/Users/hui/anaconda3/lib/python3.7/site-packages/pymysql/connections.py", line 630, in connect
    raise exc
pymysql.err.OperationalError: (2003, "Can't connect to MySQL server on 'localhost' ([Errno 61] Connection refused)")

The above exception was the direct cause of the following exception:

Traceback (most recent call last):
  File "/Users/hui/anaconda3/lib/python3.7/site-packages/flask/app.py", line 2446, in wsgi_app
    response = self.full_dispatch_request()
  File "/Users/hui/anaconda3/lib/python3.7/site-packages/flask/app.py", line 1951, in full_dispatch_request
    rv = self.handle_user_exception(e)
  File "/Users/hui/anaconda3/lib/python3.7/site-packages/flask/app.py", line 1820, in handle_user_exception
    reraise(exc_type, exc_value, tb)
  File "/Users/hui/anaconda3/lib/python3.7/site-packages/flask/_compat.py", line 39, in reraise
    raise value
  File "/Users/hui/anaconda3/lib/python3.7/site-packages/flask/app.py", line 1949, in full_dispatch_request
    rv = self.dispatch_request()
  File "/Users/hui/anaconda3/lib/python3.7/site-packages/flask/app.py", line 1935, in dispatch_request
    return self.view_functions[rule.endpoint](**req.view_args)
  File "/Users/hui/Documents/Scripts/flask/app/auth/routes.py", line 43, in register
    if form.validate_on_submit():
  File "/Users/hui/anaconda3/lib/python3.7/site-packages/flask_wtf/form.py", line 101, in validate_on_submit
    return self.is_submitted() and self.validate()
  File "/Users/hui/anaconda3/lib/python3.7/site-packages/wtforms/form.py", line 310, in validate
    return super(Form, self).validate(extra)
  File "/Users/hui/anaconda3/lib/python3.7/site-packages/wtforms/form.py", line 152, in validate
    if not field.validate(self, extra):
  File "/Users/hui/anaconda3/lib/python3.7/site-packages/wtforms/fields/core.py", line 206, in validate
    stop_validation = self._run_validation_chain(form, chain)
  File "/Users/hui/anaconda3/lib/python3.7/site-packages/wtforms/fields/core.py", line 226, in _run_validation_chain
    validator(form, self)
  File "/Users/hui/Documents/Scripts/flask/app/auth/forms.py", line 25, in validate_username
    user = User.query.filter_by(username=username.data).first()
  File "/Users/hui/anaconda3/lib/python3.7/site-packages/sqlalchemy/orm/query.py", line 3228, in first
    ret = list(self[0:1])
  File "/Users/hui/anaconda3/lib/python3.7/site-packages/sqlalchemy/orm/query.py", line 3018, in __getitem__
    return list(res)
  File "/Users/hui/anaconda3/lib/python3.7/site-packages/sqlalchemy/orm/query.py", line 3330, in __iter__
    return self._execute_and_instances(context)
  File "/Users/hui/anaconda3/lib/python3.7/site-packages/sqlalchemy/orm/query.py", line 3352, in _execute_and_instances
    querycontext, self._connection_from_session, close_with_result=True
  File "/Users/hui/anaconda3/lib/python3.7/site-packages/sqlalchemy/orm/query.py", line 3367, in _get_bind_args
    mapper=self._bind_mapper(), clause=querycontext.statement, **kw
  File "/Users/hui/anaconda3/lib/python3.7/site-packages/sqlalchemy/orm/query.py", line 3345, in _connection_from_session
    conn = self.session.connection(**kw)
  File "/Users/hui/anaconda3/lib/python3.7/site-packages/sqlalchemy/orm/session.py", line 1124, in connection
    execution_options=execution_options,
  File "/Users/hui/anaconda3/lib/python3.7/site-packages/sqlalchemy/orm/session.py", line 1130, in _connection_for_bind
    engine, execution_options
  File "/Users/hui/anaconda3/lib/python3.7/site-packages/sqlalchemy/orm/session.py", line 431, in _connection_for_bind
    conn = bind._contextual_connect()
  File "/Users/hui/anaconda3/lib/python3.7/site-packages/sqlalchemy/engine/base.py", line 2229, in _contextual_connect
    self._wrap_pool_connect(self.pool.connect, None),
  File "/Users/hui/anaconda3/lib/python3.7/site-packages/sqlalchemy/engine/base.py", line 2269, in _wrap_pool_connect
    e, dialect, self
  File "/Users/hui/anaconda3/lib/python3.7/site-packages/sqlalchemy/engine/base.py", line 1536, in _handle_dbapi_exception_noconnection
    util.raise_from_cause(sqlalchemy_exception, exc_info)
  File "/Users/hui/anaconda3/lib/python3.7/site-packages/sqlalchemy/util/compat.py", line 398, in raise_from_cause
    reraise(type(exception), exception, tb=exc_tb, cause=cause)
  File "/Users/hui/anaconda3/lib/python3.7/site-packages/sqlalchemy/util/compat.py", line 152, in reraise
    raise value.with_traceback(tb)
  File "/Users/hui/anaconda3/lib/python3.7/site-packages/sqlalchemy/engine/base.py", line 2265, in _wrap_pool_connect
    return fn()
  File "/Users/hui/anaconda3/lib/python3.7/site-packages/sqlalchemy/pool/base.py", line 363, in connect
    return _ConnectionFairy._checkout(self)
  File "/Users/hui/anaconda3/lib/python3.7/site-packages/sqlalchemy/pool/base.py", line 760, in _checkout
    fairy = _ConnectionRecord.checkout(pool)
  File "/Users/hui/anaconda3/lib/python3.7/site-packages/sqlalchemy/pool/base.py", line 492, in checkout
    rec = pool._do_get()
  File "/Users/hui/anaconda3/lib/python3.7/site-packages/sqlalchemy/pool/impl.py", line 139, in _do_get
    self._dec_overflow()
  File "/Users/hui/anaconda3/lib/python3.7/site-packages/sqlalchemy/util/langhelpers.py", line 68, in __exit__
    compat.reraise(exc_type, exc_value, exc_tb)
  File "/Users/hui/anaconda3/lib/python3.7/site-packages/sqlalchemy/util/compat.py", line 153, in reraise
    raise value
  File "/Users/hui/anaconda3/lib/python3.7/site-packages/sqlalchemy/pool/impl.py", line 136, in _do_get
    return self._create_connection()
  File "/Users/hui/anaconda3/lib/python3.7/site-packages/sqlalchemy/pool/base.py", line 308, in _create_connection
    return _ConnectionRecord(self)
  File "/Users/hui/anaconda3/lib/python3.7/site-packages/sqlalchemy/pool/base.py", line 437, in __init__
    self.__connect(first_connect_check=True)
  File "/Users/hui/anaconda3/lib/python3.7/site-packages/sqlalchemy/pool/base.py", line 639, in __connect
    connection = pool._invoke_creator(self)
  File "/Users/hui/anaconda3/lib/python3.7/site-packages/sqlalchemy/engine/strategies.py", line 114, in connect
    return dialect.connect(*cargs, **cparams)
  File "/Users/hui/anaconda3/lib/python3.7/site-packages/sqlalchemy/engine/default.py", line 453, in connect
    return self.dbapi.connect(*cargs, **cparams)
  File "/Users/hui/anaconda3/lib/python3.7/site-packages/pymysql/__init__.py", line 94, in Connect
    return Connection(*args, **kwargs)
  File "/Users/hui/anaconda3/lib/python3.7/site-packages/pymysql/connections.py", line 325, in __init__
    self.connect()
  File "/Users/hui/anaconda3/lib/python3.7/site-packages/pymysql/connections.py", line 630, in connect
    raise exc
sqlalchemy.exc.OperationalError: (pymysql.err.OperationalError) (2003, "Can't connect to MySQL server on 'localhost' ([Errno 61] Connection refused)")
(Background on this error at: http://sqlalche.me/e/e3q8)
