2019-08-17 12:05:58,342 ERROR: Exception on /index [GET] [in /Users/hui/Documents/Scripts/flask/venv/lib/python3.7/site-packages/flask/app.py:1891]
Traceback (most recent call last):
  File "/Users/hui/Documents/Scripts/flask/venv/lib/python3.7/site-packages/flask/app.py", line 2446, in wsgi_app
    response = self.full_dispatch_request()
  File "/Users/hui/Documents/Scripts/flask/venv/lib/python3.7/site-packages/flask/app.py", line 1951, in full_dispatch_request
    rv = self.handle_user_exception(e)
  File "/Users/hui/Documents/Scripts/flask/venv/lib/python3.7/site-packages/flask/app.py", line 1820, in handle_user_exception
    reraise(exc_type, exc_value, tb)
  File "/Users/hui/Documents/Scripts/flask/venv/lib/python3.7/site-packages/flask/_compat.py", line 39, in reraise
    raise value
  File "/Users/hui/Documents/Scripts/flask/venv/lib/python3.7/site-packages/flask/app.py", line 1949, in full_dispatch_request
    rv = self.dispatch_request()
  File "/Users/hui/Documents/Scripts/flask/venv/lib/python3.7/site-packages/flask/app.py", line 1935, in dispatch_request
    return self.view_functions[rule.endpoint](**req.view_args)
  File "/Users/hui/Documents/Scripts/flask/venv/lib/python3.7/site-packages/flask_login/utils.py", line 261, in decorated_view
    return func(*args, **kwargs)
  File "/Users/hui/Documents/Scripts/flask/app/main/routes.py", line 43, in index
    posts=posts.items, next_url=next_url,prev_url=prev_url)
  File "/Users/hui/Documents/Scripts/flask/venv/lib/python3.7/site-packages/flask/templating.py", line 140, in render_template
    ctx.app,
  File "/Users/hui/Documents/Scripts/flask/venv/lib/python3.7/site-packages/flask/templating.py", line 120, in _render
    rv = template.render(context)
  File "/Users/hui/Documents/Scripts/flask/venv/lib/python3.7/site-packages/jinja2/asyncsupport.py", line 76, in render
    return original_render(self, *args, **kwargs)
  File "/Users/hui/Documents/Scripts/flask/venv/lib/python3.7/site-packages/jinja2/environment.py", line 1008, in render
    return self.environment.handle_exception(exc_info, True)
  File "/Users/hui/Documents/Scripts/flask/venv/lib/python3.7/site-packages/jinja2/environment.py", line 780, in handle_exception
    reraise(exc_type, exc_value, tb)
  File "/Users/hui/Documents/Scripts/flask/venv/lib/python3.7/site-packages/jinja2/_compat.py", line 37, in reraise
    raise value.with_traceback(tb)
  File "/Users/hui/Documents/Scripts/flask/app/templates/index.html", line 37, in top-level template code
    {% if next_url %}
  File "/Users/hui/Documents/Scripts/flask/app/templates/base.html", line 1, in top-level template code
    {% extends "bootstrap/base.html" %}
  File "/Users/hui/Documents/Scripts/flask/venv/lib/python3.7/site-packages/flask_bootstrap/templates/bootstrap/base.html", line 1, in top-level template code
    {% block doc -%}
  File "/Users/hui/Documents/Scripts/flask/venv/lib/python3.7/site-packages/flask_bootstrap/templates/bootstrap/base.html", line 4, in block "doc"
    {%- block html %}
  File "/Users/hui/Documents/Scripts/flask/venv/lib/python3.7/site-packages/flask_bootstrap/templates/bootstrap/base.html", line 20, in block "html"
    {% block body -%}
  File "/Users/hui/Documents/Scripts/flask/venv/lib/python3.7/site-packages/flask_bootstrap/templates/bootstrap/base.html", line 23, in block "body"
    {% block content -%}
  File "/Users/hui/Documents/Scripts/flask/app/templates/base.html", line 58, in block "content"
    {% block app_content %}{% endblock %}
  File "/Users/hui/Documents/Scripts/flask/app/templates/index.html", line 11, in block "app_content"
    {% include '_post.html' %}
  File "/Users/hui/Documents/Scripts/flask/app/templates/_post.html", line 40, in top-level template code
    <a href="{{ url_for('user',username=post.author.username) }}">
  File "/Users/hui/Documents/Scripts/flask/venv/lib/python3.7/site-packages/flask/helpers.py", line 370, in url_for
    return appctx.app.handle_url_build_error(error, endpoint, values)
  File "/Users/hui/Documents/Scripts/flask/venv/lib/python3.7/site-packages/flask/app.py", line 2215, in handle_url_build_error
    reraise(exc_type, exc_value, tb)
  File "/Users/hui/Documents/Scripts/flask/venv/lib/python3.7/site-packages/flask/_compat.py", line 39, in reraise
    raise value
  File "/Users/hui/Documents/Scripts/flask/venv/lib/python3.7/site-packages/flask/helpers.py", line 358, in url_for
    endpoint, values, method=method, force_external=external
  File "/Users/hui/Documents/Scripts/flask/venv/lib/python3.7/site-packages/werkzeug/routing.py", line 2020, in build
    raise BuildError(endpoint, values, method, self)
werkzeug.routing.BuildError: Could not build url for endpoint 'user' with values ['username']. Did you mean 'main.user' instead?
2019-08-17 12:10:20,137 ERROR: Exception on / [GET] [in /Users/hui/Documents/Scripts/flask/venv/lib/python3.7/site-packages/flask/app.py:1891]
Traceback (most recent call last):
  File "/Users/hui/Documents/Scripts/flask/venv/lib/python3.7/site-packages/flask/app.py", line 2446, in wsgi_app
    response = self.full_dispatch_request()
  File "/Users/hui/Documents/Scripts/flask/venv/lib/python3.7/site-packages/flask/app.py", line 1951, in full_dispatch_request
    rv = self.handle_user_exception(e)
  File "/Users/hui/Documents/Scripts/flask/venv/lib/python3.7/site-packages/flask/app.py", line 1820, in handle_user_exception
    reraise(exc_type, exc_value, tb)
  File "/Users/hui/Documents/Scripts/flask/venv/lib/python3.7/site-packages/flask/_compat.py", line 39, in reraise
    raise value
  File "/Users/hui/Documents/Scripts/flask/venv/lib/python3.7/site-packages/flask/app.py", line 1949, in full_dispatch_request
    rv = self.dispatch_request()
  File "/Users/hui/Documents/Scripts/flask/venv/lib/python3.7/site-packages/flask/app.py", line 1935, in dispatch_request
    return self.view_functions[rule.endpoint](**req.view_args)
  File "/Users/hui/Documents/Scripts/flask/venv/lib/python3.7/site-packages/flask_login/utils.py", line 261, in decorated_view
    return func(*args, **kwargs)
  File "/Users/hui/Documents/Scripts/flask/app/main/routes.py", line 43, in index
    posts=posts.items, next_url=next_url,prev_url=prev_url)
  File "/Users/hui/Documents/Scripts/flask/venv/lib/python3.7/site-packages/flask/templating.py", line 140, in render_template
    ctx.app,
  File "/Users/hui/Documents/Scripts/flask/venv/lib/python3.7/site-packages/flask/templating.py", line 120, in _render
    rv = template.render(context)
  File "/Users/hui/Documents/Scripts/flask/venv/lib/python3.7/site-packages/jinja2/asyncsupport.py", line 76, in render
    return original_render(self, *args, **kwargs)
  File "/Users/hui/Documents/Scripts/flask/venv/lib/python3.7/site-packages/jinja2/environment.py", line 1008, in render
    return self.environment.handle_exception(exc_info, True)
  File "/Users/hui/Documents/Scripts/flask/venv/lib/python3.7/site-packages/jinja2/environment.py", line 780, in handle_exception
    reraise(exc_type, exc_value, tb)
  File "/Users/hui/Documents/Scripts/flask/venv/lib/python3.7/site-packages/jinja2/_compat.py", line 37, in reraise
    raise value.with_traceback(tb)
  File "/Users/hui/Documents/Scripts/flask/app/templates/index.html", line 37, in top-level template code
    {% if next_url %}
  File "/Users/hui/Documents/Scripts/flask/app/templates/base.html", line 1, in top-level template code
    {% extends "bootstrap/base.html" %}
  File "/Users/hui/Documents/Scripts/flask/venv/lib/python3.7/site-packages/flask_bootstrap/templates/bootstrap/base.html", line 1, in top-level template code
    {% block doc -%}
  File "/Users/hui/Documents/Scripts/flask/venv/lib/python3.7/site-packages/flask_bootstrap/templates/bootstrap/base.html", line 4, in block "doc"
    {%- block html %}
  File "/Users/hui/Documents/Scripts/flask/venv/lib/python3.7/site-packages/flask_bootstrap/templates/bootstrap/base.html", line 20, in block "html"
    {% block body -%}
  File "/Users/hui/Documents/Scripts/flask/venv/lib/python3.7/site-packages/flask_bootstrap/templates/bootstrap/base.html", line 23, in block "body"
    {% block content -%}
  File "/Users/hui/Documents/Scripts/flask/app/templates/base.html", line 58, in block "content"
    {% block app_content %}{% endblock %}
  File "/Users/hui/Documents/Scripts/flask/app/templates/index.html", line 11, in block "app_content"
    {% include '_post.html' %}
  File "/Users/hui/Documents/Scripts/flask/app/templates/_post.html", line 40, in top-level template code
    <a href="{{ url_for('user',username=post.author.username) }}">
  File "/Users/hui/Documents/Scripts/flask/venv/lib/python3.7/site-packages/flask/helpers.py", line 370, in url_for
    return appctx.app.handle_url_build_error(error, endpoint, values)
  File "/Users/hui/Documents/Scripts/flask/venv/lib/python3.7/site-packages/flask/app.py", line 2215, in handle_url_build_error
    reraise(exc_type, exc_value, tb)
  File "/Users/hui/Documents/Scripts/flask/venv/lib/python3.7/site-packages/flask/_compat.py", line 39, in reraise
    raise value
  File "/Users/hui/Documents/Scripts/flask/venv/lib/python3.7/site-packages/flask/helpers.py", line 358, in url_for
    endpoint, values, method=method, force_external=external
  File "/Users/hui/Documents/Scripts/flask/venv/lib/python3.7/site-packages/werkzeug/routing.py", line 2020, in build
    raise BuildError(endpoint, values, method, self)
werkzeug.routing.BuildError: Could not build url for endpoint 'user' with values ['username']. Did you mean 'main.user' instead?
2019-08-17 18:34:59,022 INFO: Microblog startup [in /Users/hui/Documents/Scripts/flask/app/__init__.py:76]
2019-08-17 18:35:06,347 INFO: Microblog startup [in /Users/hui/Documents/Scripts/flask/app/__init__.py:76]
