2019-08-06 22:34:08,777 ERROR: Exception on /reset_password_request [POST] [in /Users/hui/Documents/Scripts/flask/venv/lib/python3.7/site-packages/flask/app.py:1891]
Traceback (most recent call last):
  File "/Users/hui/Documents/Scripts/flask/venv/lib/python3.7/site-packages/flask/app.py", line 2446, in wsgi_app
    response = self.full_dispatch_request()
  File "/Users/hui/Documents/Scripts/flask/venv/lib/python3.7/site-packages/flask/app.py", line 1951, in full_dispatch_request
    rv = self.handle_user_exception(e)
  File "/Users/hui/Documents/Scripts/flask/venv/lib/python3.7/site-packages/flask/app.py", line 1820, in handle_user_exception
    reraise(exc_type, exc_value, tb)
  File "/Users/hui/Documents/Scripts/flask/venv/lib/python3.7/site-packages/flask/_compat.py", line 39, in reraise
    raise value
  File "/Users/hui/Documents/Scripts/flask/venv/lib/python3.7/site-packages/flask/app.py", line 1949, in full_dispatch_request
    rv = self.dispatch_request()
  File "/Users/hui/Documents/Scripts/flask/venv/lib/python3.7/site-packages/flask/app.py", line 1935, in dispatch_request
    return self.view_functions[rule.endpoint](**req.view_args)
  File "/Users/hui/Documents/Scripts/flask/app/routes.py", line 163, in reset_password_request
    send_password_reset_email(user)
  File "/Users/hui/Documents/Scripts/flask/app/email.py", line 23, in send_password_reset_email
    text_body=render_template('email/reset_password.txt',user=user,token=token),
  File "/Users/hui/Documents/Scripts/flask/venv/lib/python3.7/site-packages/flask/templating.py", line 140, in render_template
    ctx.app,
  File "/Users/hui/Documents/Scripts/flask/venv/lib/python3.7/site-packages/flask/templating.py", line 120, in _render
    rv = template.render(context)
  File "/Users/hui/Documents/Scripts/flask/venv/lib/python3.7/site-packages/jinja2/asyncsupport.py", line 76, in render
    return original_render(self, *args, **kwargs)
  File "/Users/hui/Documents/Scripts/flask/venv/lib/python3.7/site-packages/jinja2/environment.py", line 1008, in render
    return self.environment.handle_exception(exc_info, True)
  File "/Users/hui/Documents/Scripts/flask/venv/lib/python3.7/site-packages/jinja2/environment.py", line 780, in handle_exception
    reraise(exc_type, exc_value, tb)
  File "/Users/hui/Documents/Scripts/flask/venv/lib/python3.7/site-packages/jinja2/_compat.py", line 37, in reraise
    raise value.with_traceback(tb)
  File "/Users/hui/Documents/Scripts/flask/app/templates/email/reset_password.txt", line 5, in top-level template code
    {{ url_for('reset_password', token=token, _external=True) }}
  File "/Users/hui/Documents/Scripts/flask/venv/lib/python3.7/site-packages/flask/helpers.py", line 370, in url_for
    return appctx.app.handle_url_build_error(error, endpoint, values)
  File "/Users/hui/Documents/Scripts/flask/venv/lib/python3.7/site-packages/flask/app.py", line 2215, in handle_url_build_error
    reraise(exc_type, exc_value, tb)
  File "/Users/hui/Documents/Scripts/flask/venv/lib/python3.7/site-packages/flask/_compat.py", line 39, in reraise
    raise value
  File "/Users/hui/Documents/Scripts/flask/venv/lib/python3.7/site-packages/flask/helpers.py", line 358, in url_for
    endpoint, values, method=method, force_external=external
  File "/Users/hui/Documents/Scripts/flask/venv/lib/python3.7/site-packages/werkzeug/routing.py", line 2020, in build
    raise BuildError(endpoint, values, method, self)
werkzeug.routing.BuildError: Could not build url for endpoint 'reset_password' with values ['token']. Did you mean 'reset_passowrd' instead?
2019-08-06 22:35:39,957 ERROR: Exception on /reset_password_request [POST] [in /Users/hui/Documents/Scripts/flask/venv/lib/python3.7/site-packages/flask/app.py:1891]
Traceback (most recent call last):
  File "/Users/hui/Documents/Scripts/flask/venv/lib/python3.7/site-packages/flask/app.py", line 2446, in wsgi_app
    response = self.full_dispatch_request()
  File "/Users/hui/Documents/Scripts/flask/venv/lib/python3.7/site-packages/flask/app.py", line 1951, in full_dispatch_request
    rv = self.handle_user_exception(e)
  File "/Users/hui/Documents/Scripts/flask/venv/lib/python3.7/site-packages/flask/app.py", line 1820, in handle_user_exception
    reraise(exc_type, exc_value, tb)
  File "/Users/hui/Documents/Scripts/flask/venv/lib/python3.7/site-packages/flask/_compat.py", line 39, in reraise
    raise value
  File "/Users/hui/Documents/Scripts/flask/venv/lib/python3.7/site-packages/flask/app.py", line 1949, in full_dispatch_request
    rv = self.dispatch_request()
  File "/Users/hui/Documents/Scripts/flask/venv/lib/python3.7/site-packages/flask/app.py", line 1935, in dispatch_request
    return self.view_functions[rule.endpoint](**req.view_args)
  File "/Users/hui/Documents/Scripts/flask/app/routes.py", line 163, in reset_password_request
    send_password_reset_email(user)
  File "/Users/hui/Documents/Scripts/flask/app/email.py", line 24, in send_password_reset_email
    html_body=render_template('email/reset_password.html',user=user,token=token))
  File "/Users/hui/Documents/Scripts/flask/venv/lib/python3.7/site-packages/flask/templating.py", line 140, in render_template
    ctx.app,
  File "/Users/hui/Documents/Scripts/flask/venv/lib/python3.7/site-packages/flask/templating.py", line 120, in _render
    rv = template.render(context)
  File "/Users/hui/Documents/Scripts/flask/venv/lib/python3.7/site-packages/jinja2/asyncsupport.py", line 76, in render
    return original_render(self, *args, **kwargs)
  File "/Users/hui/Documents/Scripts/flask/venv/lib/python3.7/site-packages/jinja2/environment.py", line 1008, in render
    return self.environment.handle_exception(exc_info, True)
  File "/Users/hui/Documents/Scripts/flask/venv/lib/python3.7/site-packages/jinja2/environment.py", line 780, in handle_exception
    reraise(exc_type, exc_value, tb)
  File "/Users/hui/Documents/Scripts/flask/venv/lib/python3.7/site-packages/jinja2/_compat.py", line 37, in reraise
    raise value.with_traceback(tb)
  File "/Users/hui/Documents/Scripts/flask/app/templates/email/reset_password.html", line 4, in top-level template code
    <a href="{{url_for('reset_passowrd',token=token,_external=True)}}">Click Here</a>.
  File "/Users/hui/Documents/Scripts/flask/venv/lib/python3.7/site-packages/flask/helpers.py", line 370, in url_for
    return appctx.app.handle_url_build_error(error, endpoint, values)
  File "/Users/hui/Documents/Scripts/flask/venv/lib/python3.7/site-packages/flask/app.py", line 2215, in handle_url_build_error
    reraise(exc_type, exc_value, tb)
  File "/Users/hui/Documents/Scripts/flask/venv/lib/python3.7/site-packages/flask/_compat.py", line 39, in reraise
    raise value
  File "/Users/hui/Documents/Scripts/flask/venv/lib/python3.7/site-packages/flask/helpers.py", line 358, in url_for
    endpoint, values, method=method, force_external=external
  File "/Users/hui/Documents/Scripts/flask/venv/lib/python3.7/site-packages/werkzeug/routing.py", line 2020, in build
    raise BuildError(endpoint, values, method, self)
werkzeug.routing.BuildError: Could not build url for endpoint 'reset_passowrd' with values ['token']. Did you mean 'reset_password' instead?
