2019-08-05 23:08:40,496 ERROR: Exception on /favicon.ico [GET] [in /Users/hui/Documents/Scripts/flask/venv/lib/python3.7/site-packages/flask/app.py:1891]
Traceback (most recent call last):
  File "/Users/hui/Documents/Scripts/flask/venv/lib/python3.7/site-packages/flask/app.py", line 1949, in full_dispatch_request
    rv = self.dispatch_request()
  File "/Users/hui/Documents/Scripts/flask/venv/lib/python3.7/site-packages/flask/app.py", line 1925, in dispatch_request
    self.raise_routing_exception(req)
  File "/Users/hui/Documents/Scripts/flask/venv/lib/python3.7/site-packages/flask/app.py", line 1907, in raise_routing_exception
    raise request.routing_exception
  File "/Users/hui/Documents/Scripts/flask/venv/lib/python3.7/site-packages/flask/ctx.py", line 350, in match_request
    result = self.url_adapter.match(return_rule=True)
  File "/Users/hui/Documents/Scripts/flask/venv/lib/python3.7/site-packages/werkzeug/routing.py", line 1799, in match
    raise NotFound()
werkzeug.exceptions.NotFound: 404 Not Found: The requested URL was not found on the server. If you entered the URL manually please check your spelling and try again.

During handling of the above exception, another exception occurred:

Traceback (most recent call last):
  File "/Users/hui/Documents/Scripts/flask/venv/lib/python3.7/site-packages/flask/app.py", line 2446, in wsgi_app
    response = self.full_dispatch_request()
  File "/Users/hui/Documents/Scripts/flask/venv/lib/python3.7/site-packages/flask/app.py", line 1951, in full_dispatch_request
    rv = self.handle_user_exception(e)
  File "/Users/hui/Documents/Scripts/flask/venv/lib/python3.7/site-packages/flask/app.py", line 1815, in handle_user_exception
    return self.handle_http_exception(e)
  File "/Users/hui/Documents/Scripts/flask/venv/lib/python3.7/site-packages/flask/app.py", line 1743, in handle_http_exception
    return handler(e)
  File "/Users/hui/Documents/Scripts/flask/app/errors.py", line 6, in not_found_error
    return render_template('40t.html'), 404
  File "/Users/hui/Documents/Scripts/flask/venv/lib/python3.7/site-packages/flask/templating.py", line 138, in render_template
    ctx.app.jinja_env.get_or_select_template(template_name_or_list),
  File "/Users/hui/Documents/Scripts/flask/venv/lib/python3.7/site-packages/jinja2/environment.py", line 869, in get_or_select_template
    return self.get_template(template_name_or_list, parent, globals)
  File "/Users/hui/Documents/Scripts/flask/venv/lib/python3.7/site-packages/jinja2/environment.py", line 830, in get_template
    return self._load_template(name, self.make_globals(globals))
  File "/Users/hui/Documents/Scripts/flask/venv/lib/python3.7/site-packages/jinja2/environment.py", line 804, in _load_template
    template = self.loader.load(self, name, globals)
  File "/Users/hui/Documents/Scripts/flask/venv/lib/python3.7/site-packages/jinja2/loaders.py", line 113, in load
    source, filename, uptodate = self.get_source(environment, name)
  File "/Users/hui/Documents/Scripts/flask/venv/lib/python3.7/site-packages/flask/templating.py", line 60, in get_source
    return self._get_source_fast(environment, template)
  File "/Users/hui/Documents/Scripts/flask/venv/lib/python3.7/site-packages/flask/templating.py", line 89, in _get_source_fast
    raise TemplateNotFound(template)
jinja2.exceptions.TemplateNotFound: 40t.html
2019-08-05 23:11:23,306 ERROR: Exception on /user/user1 [GET] [in /Users/hui/Documents/Scripts/flask/venv/lib/python3.7/site-packages/flask/app.py:1891]
Traceback (most recent call last):
  File "/Users/hui/Documents/Scripts/flask/venv/lib/python3.7/site-packages/flask/app.py", line 2446, in wsgi_app
    response = self.full_dispatch_request()
  File "/Users/hui/Documents/Scripts/flask/venv/lib/python3.7/site-packages/flask/app.py", line 1951, in full_dispatch_request
    rv = self.handle_user_exception(e)
  File "/Users/hui/Documents/Scripts/flask/venv/lib/python3.7/site-packages/flask/app.py", line 1820, in handle_user_exception
    reraise(exc_type, exc_value, tb)
  File "/Users/hui/Documents/Scripts/flask/venv/lib/python3.7/site-packages/flask/_compat.py", line 39, in reraise
    raise value
  File "/Users/hui/Documents/Scripts/flask/venv/lib/python3.7/site-packages/flask/app.py", line 1949, in full_dispatch_request
    rv = self.dispatch_request()
  File "/Users/hui/Documents/Scripts/flask/venv/lib/python3.7/site-packages/flask/app.py", line 1935, in dispatch_request
    return self.view_functions[rule.endpoint](**req.view_args)
  File "/Users/hui/Documents/Scripts/flask/venv/lib/python3.7/site-packages/flask_login/utils.py", line 261, in decorated_view
    return func(*args, **kwargs)
  File "/Users/hui/Documents/Scripts/flask/app/routes.py", line 78, in user
    posts = current_user.posts().all()
TypeError: 'AppenderBaseQuery' object is not callable
2019-08-05 23:15:41,232 ERROR: Exception on /user/user1 [GET] [in /Users/hui/Documents/Scripts/flask/venv/lib/python3.7/site-packages/flask/app.py:1891]
Traceback (most recent call last):
  File "/Users/hui/Documents/Scripts/flask/venv/lib/python3.7/site-packages/flask/app.py", line 2446, in wsgi_app
    response = self.full_dispatch_request()
  File "/Users/hui/Documents/Scripts/flask/venv/lib/python3.7/site-packages/flask/app.py", line 1951, in full_dispatch_request
    rv = self.handle_user_exception(e)
  File "/Users/hui/Documents/Scripts/flask/venv/lib/python3.7/site-packages/flask/app.py", line 1820, in handle_user_exception
    reraise(exc_type, exc_value, tb)
  File "/Users/hui/Documents/Scripts/flask/venv/lib/python3.7/site-packages/flask/_compat.py", line 39, in reraise
    raise value
  File "/Users/hui/Documents/Scripts/flask/venv/lib/python3.7/site-packages/flask/app.py", line 1949, in full_dispatch_request
    rv = self.dispatch_request()
  File "/Users/hui/Documents/Scripts/flask/venv/lib/python3.7/site-packages/flask/app.py", line 1935, in dispatch_request
    return self.view_functions[rule.endpoint](**req.view_args)
  File "/Users/hui/Documents/Scripts/flask/venv/lib/python3.7/site-packages/flask_login/utils.py", line 261, in decorated_view
    return func(*args, **kwargs)
  File "/Users/hui/Documents/Scripts/flask/app/routes.py", line 78, in user
    posts = User.query.filter_by(username=username).posts
AttributeError: 'BaseQuery' object has no attribute 'posts'
2019-08-06 22:32:42,207 ERROR: Exception on /reset_password_request [POST] [in /Users/hui/Documents/Scripts/flask/venv/lib/python3.7/site-packages/flask/app.py:1891]
Traceback (most recent call last):
  File "/Users/hui/Documents/Scripts/flask/venv/lib/python3.7/site-packages/flask/app.py", line 2446, in wsgi_app
    response = self.full_dispatch_request()
  File "/Users/hui/Documents/Scripts/flask/venv/lib/python3.7/site-packages/flask/app.py", line 1951, in full_dispatch_request
    rv = self.handle_user_exception(e)
  File "/Users/hui/Documents/Scripts/flask/venv/lib/python3.7/site-packages/flask/app.py", line 1820, in handle_user_exception
    reraise(exc_type, exc_value, tb)
  File "/Users/hui/Documents/Scripts/flask/venv/lib/python3.7/site-packages/flask/_compat.py", line 39, in reraise
    raise value
  File "/Users/hui/Documents/Scripts/flask/venv/lib/python3.7/site-packages/flask/app.py", line 1949, in full_dispatch_request
    rv = self.dispatch_request()
  File "/Users/hui/Documents/Scripts/flask/venv/lib/python3.7/site-packages/flask/app.py", line 1935, in dispatch_request
    return self.view_functions[rule.endpoint](**req.view_args)
  File "/Users/hui/Documents/Scripts/flask/app/routes.py", line 163, in reset_password_request
    send_password_reset_email(user)
  File "/Users/hui/Documents/Scripts/flask/app/email.py", line 23, in send_password_reset_email
    text_body=render_template('email/reset_passowrd.txt',user=user,token=token),
  File "/Users/hui/Documents/Scripts/flask/venv/lib/python3.7/site-packages/flask/templating.py", line 138, in render_template
    ctx.app.jinja_env.get_or_select_template(template_name_or_list),
  File "/Users/hui/Documents/Scripts/flask/venv/lib/python3.7/site-packages/jinja2/environment.py", line 869, in get_or_select_template
    return self.get_template(template_name_or_list, parent, globals)
  File "/Users/hui/Documents/Scripts/flask/venv/lib/python3.7/site-packages/jinja2/environment.py", line 830, in get_template
    return self._load_template(name, self.make_globals(globals))
  File "/Users/hui/Documents/Scripts/flask/venv/lib/python3.7/site-packages/jinja2/environment.py", line 804, in _load_template
    template = self.loader.load(self, name, globals)
  File "/Users/hui/Documents/Scripts/flask/venv/lib/python3.7/site-packages/jinja2/loaders.py", line 113, in load
    source, filename, uptodate = self.get_source(environment, name)
  File "/Users/hui/Documents/Scripts/flask/venv/lib/python3.7/site-packages/flask/templating.py", line 60, in get_source
    return self._get_source_fast(environment, template)
  File "/Users/hui/Documents/Scripts/flask/venv/lib/python3.7/site-packages/flask/templating.py", line 89, in _get_source_fast
    raise TemplateNotFound(template)
jinja2.exceptions.TemplateNotFound: email/reset_passowrd.txt
